Workbook
Name TasaIVA: Configuracion!$B$11
Name TasaPPM: Configuracion!$B$12
Name TasaRenta: Configuracion!$B$13
Name AnioTrabajo: Configuracion!$B$7
Name MesTrabajo: Configuracion!$B$8

Sheet Comprobantes
A1: Comprobantes — lo que entra por Telegram
A2: Cada foto confirmada es una fila. Los gastos fijos y variables suman desde aquí. No borres las columnas grises.
A3: Amarillo = datos del bot. Gris = fórmulas (IVA, total, año y mes).
A5: N° | B5: Fecha | C5: Tipo | D5: Categoría | E5: Proveedor / cliente | F5: N° documento | G5: Descripción | H5: Neto | I5: Afecto IVA | J5: IVA | K5: Total | L5: Año | M5: Mes | N5: Origen | O5: Estado | P5: Archivo | Q5: Huella
A6: 1 | B6: 46249 | C6: Gasto fijo | D6: Arriendo local / patio | G6: Saldo que ya estaba anotado en la planilla | H6: 2800000 | I6: No | J6: =IF(H6="","",IF(I6="Sí",ROUND(H6*Configuracion!$B$11,0),0)) | K6: =IF(H6="","",H6+J6) | L6: =IF(B6="","",YEAR(B6)) | M6: =IF(B6="","",MONTH(B6)) | N6: Planilla | O6: Confirmado
A7: 2 | B7: 46249 | C7: Gasto fijo | D7: Sueldos (líquidos) | G7: Saldo que ya estaba anotado en la planilla | H7: 4200000 | I7: No | J7: =IF(H7="","",IF(I7="Sí",ROUND(H7*Configuracion!$B$11,0),0)) | K7: =IF(H7="","",H7+J7) | L7: =IF(B7="","",YEAR(B7)) | M7: =IF(B7="","",MONTH(B7)) | N7: Planilla | O7: Confirmado
A8: 3 | B8: 46249 | C8: Gasto fijo | D8: Leyes sociales empleador | G8: Saldo que ya estaba anotado en la planilla | H8: 1150000 | I8: No | J8: =IF(H8="","",IF(I8="Sí",ROUND(H8*Configuracion!$B$11,0),0)) | K8: =IF(H8="","",H8+J8) | L8: =IF(B8="","",YEAR(B8)) | M8: =IF(B8="","",MONTH(B8)) | N8: Planilla | O8: Confirmado
A9: 4 | B9: 46249 | C9: Gasto fijo | D9: Honorarios contador | G9: Saldo que ya estaba anotado en la planilla | H9: 250000 | I9: No | J9: =IF(H9="","",IF(I9="Sí",ROUND(H9*Configuracion!$B$11,0),0)) | K9: =IF(H9="","",H9+J9) | L9: =IF(B9="","",YEAR(B9)) | M9: =IF(B9="","",MONTH(B9)) | N9: Planilla | O9: Confirmado
A10: 5 | B10: 46249 | C10: Gasto fijo | D10: Seguros (local, stock, RC) | G10: Saldo que ya estaba anotado en la planilla | H10: 180000 | I10: No | J10: =IF(H10="","",IF(I10="Sí",ROUND(H10*Configuracion!$B$11,0),0)) | K10: =IF(H10="","",H10+J10) | L10: =IF(B10="","",YEAR(B10)) | M10: =IF(B10="","",MONTH(B10)) | N10: Planilla | O10: Confirmado
A11: 6 | B11: 46249 | C11: Gasto fijo | D11: Electricidad | G11: Saldo que ya estaba anotado en la planilla | H11: 220000 | I11: Sí | J11: =IF(H11="","",IF(I11="Sí",ROUND(H11*Configuracion!$B$11,0),0)) | K11: =IF(H11="","",H11+J11) | L11: =IF(B11="","",YEAR(B11)) | M11: =IF(B11="","",MONTH(B11)) | N11: Planilla | O11: Confirmado
A12: 7 | B12: 46249 | C12: Gasto fijo | D12: Internet y telefonía | G12: Saldo que ya estaba anotado en la planilla | H12: 89000 | I12: Sí | J12: =IF(H12="","",IF(I12="Sí",ROUND(H12*Configuracion!$B$11,0),0)) | K12: =IF(H12="","",H12+J12) | L12: =IF(B12="","",YEAR(B12)) | M12: =IF(B12="","",MONTH(B12)) | N12: Planilla | O12: Confirmado
A13: 8 | B13: 46249 | C13: Gasto fijo | D13: Alarma / seguridad | G13: Saldo que ya estaba anotado en la planilla | H13: 45000 | I13: Sí | J13: =IF(H13="","",IF(I13="Sí",ROUND(H13*Configuracion!$B$11,0),0)) | K13: =IF(H13="","",H13+J13) | L13: =IF(B13="","",YEAR(B13)) | M13: =IF(B13="","",MONTH(B13)) | N13: Planilla | O13: Confirmado
A14: 9 | B14: 46249 | C14: Gasto fijo | D14: Aseo | G14: Saldo que ya estaba anotado en la planilla | H14: 80000 | I14: Sí | J14: =IF(H14="","",IF(I14="Sí",ROUND(H14*Configuracion!$B$11,0),0)) | K14: =IF(H14="","",H14+J14) | L14: =IF(B14="","",YEAR(B14)) | M14: =IF(B14="","",MONTH(B14)) | N14: Planilla | O14: Confirmado
A15: 10 | B15: 46249 | C15: Gasto fijo | D15: Software / facturación electrónica | G15: Saldo que ya estaba anotado en la planilla | H15: 65000 | I15: Sí | J15: =IF(H15="","",IF(I15="Sí",ROUND(H15*Configuracion!$B$11,0),0)) | K15: =IF(H15="","",H15+J15) | L15: =IF(B15="","",YEAR(B15)) | M15: =IF(B15="","",MONTH(B15)) | N15: Planilla | O15: Confirmado
A16: 11 | B16: 46249 | C16: Gasto fijo | D16: Publicidad fija (portales, redes) | G16: Saldo que ya estaba anotado en la planilla | H16: 350000 | I16: Sí | J16: =IF(H16="","",IF(I16="Sí",ROUND(H16*Configuracion!$B$11,0),0)) | K16: =IF(H16="","",H16+J16) | L16: =IF(B16="","",YEAR(B16)) | M16: =IF(B16="","",MONTH(B16)) | N16: Planilla | O16: Confirmado
A17: 12 | B17: 46249 | C17: Gasto variable | D17: Publicidad de campañas | G17: Saldo que ya estaba anotado en la planilla | H17: 280000 | I17: Sí | J17: =IF(H17="","",IF(I17="Sí",ROUND(H17*Configuracion!$B$11,0),0)) | K17: =IF(H17="","",H17+J17) | L17: =IF(B17="","",YEAR(B17)) | M17: =IF(B17="","",MONTH(B17)) | N17: Planilla | O17: Confirmado
... A21: 16 | B21: 46249 | C21: Gasto variable | D21: Comisiones Transbank / Webpay | G21: Saldo que ya estaba anotado en la planilla | H21: 45000 | I21: Sí | J21: =IF(H21="","",IF(I21="Sí",ROUND(H21*Configuracion!$B$11,0),0)) | K21: =IF(H21="","",H21+J21) | L21: =IF(B21="","",YEAR(B21)) | M21: =IF(B21="","",MONTH(B21)) | N21: Planilla | O21: Confirmado
A22: 17 | B22: 46288 | C22: Gasto variable | D22: Transferencia / notaría / TAG | E22: Servipag | F22: 18590912 | G22: Pago de cuentas de autopistas (Ruta 78, Autopase, Vespucio Sur, Costanera Norte) | H22: 58119 | I22: Sí | J22: =IF(H22="","",IF(I22="Sí",ROUND(H22*Configuracion!$B$11,0),0)) | K22: =IF(H22="","",H22+J22) | L22: =IF(B22="","",YEAR(B22)) | M22: =IF(B22="","",MONTH(B22)) | N22: Telegram | O22: Confirmado | P22: data/comprobantes/2026-09/5d504524720b11c3.jpg | Q22: 5d504524720b11c3
J23: =IF(H23="","",IF(I23="Sí",ROUND(H23*Configuracion!$B$11,0),0)) | K23: =IF(H23="","",H23+J23) | L23: =IF(B23="","",YEAR(B23)) | M23: =IF(B23="","",MONTH(B23))
J24: =IF(H24="","",IF(I24="Sí",ROUND(H24*Configuracion!$B$11,0),0)) | K24: =IF(H24="","",H24+J24) | L24: =IF(B24="","",YEAR(B24)) | M24: =IF(B24="","",MONTH(B24))
J25: =IF(H25="","",IF(I25="Sí",ROUND(H25*Configuracion!$B$11,0),0)) | K25: =IF(H25="","",H25+J25) | L25: =IF(B25="","",YEAR(B25)) | M25: =IF(B25="","",MONTH(B25))
J26: =IF(H26="","",IF(I26="Sí",ROUND(H26*Configuracion!$B$11,0),0)) | K26: =IF(H26="","",H26+J26) | L26: =IF(B26="","",YEAR(B26)) | M26: =IF(B26="","",MONTH(B26))
J27: =IF(H27="","",IF(I27="Sí",ROUND(H27*Configuracion!$B$11,0),0)) | K27: =IF(H27="","",H27+J27) | L27: =IF(B27="","",YEAR(B27)) | M27: =IF(B27="","",MONTH(B27))
J28: =IF(H28="","",IF(I28="Sí",ROUND(H28*Configuracion!$B$11,0),0)) | K28: =IF(H28="","",H28+J28) | L28: =IF(B28="","",YEAR(B28)) | M28: =IF(B28="","",MONTH(B28))
J29: =IF(H29="","",IF(I29="Sí",ROUND(H29*Configuracion!$B$11,0),0)) | K29: =IF(H29="","",H29+J29) | L29: =IF(B29="","",YEAR(B29)) | M29: =IF(B29="","",MONTH(B29))
J30: =IF(H30="","",IF(I30="Sí",ROUND(H30*Configuracion!$B$11,0),0)) | K30: =IF(H30="","",H30+J30) | L30: =IF(B30="","",YEAR(B30)) | M30: =IF(B30="","",MONTH(B30))
J31: =IF(H31="","",IF(I31="Sí",ROUND(H31*Configuracion!$B$11,0),0)) | K31: =IF(H31="","",H31+J31) | L31: =IF(B31="","",YEAR(B31)) | M31: =IF(B31="","",MONTH(B31))
J32: =IF(H32="","",IF(I32="Sí",ROUND(H32*Configuracion!$B$11,0),0)) | K32: =IF(H32="","",H32+J32) | L32: =IF(B32="","",YEAR(B32)) | M32: =IF(B32="","",MONTH(B32))
J33: =IF(H33="","",IF(I33="Sí",ROUND(H33*Configuracion!$B$11,0),0)) | K33: =IF(H33="","",H33+J33) | L33: =IF(B33="","",YEAR(B33)) | M33: =IF(B33="","",MONTH(B33))
J34: =IF(H34="","",IF(I34="Sí",ROUND(H34*Configuracion!$B$11,0),0)) | K34: =IF(H34="","",H34+J34) | L34: =IF(B34="","",YEAR(B34)) | M34: =IF(B34="","",MONTH(B34))
... J2005: =IF(H2005="","",IF(I2005="Sí",ROUND(H2005*Configuracion!$B$11,0),0)) | K2005: =IF(H2005="","",H2005+J2005) | L2005: =IF(B2005="","",YEAR(B2005)) | M2005: =IF(B2005="","",MONTH(B2005))

Sheet Instrucciones
A1: Cómo usar esta planilla
A2: Control de ingresos, gastos, IVA y PPM — Automotora
B4: Color de las celdas
B5: Amarillo claro: tú escribes. Gris azulado: fórmula, no la borres. Los totales y el resumen se calculan solos.
B7: Orden de trabajo cada mes
B8: 1) En Configuracion elige el año y el mes que estás cerrando. 2) Carga ventas de autos (propios y consignación) en Ventas_Autos. 3) Carga taller y repuestos en Taller_Repuestos. 4) Completa Gastos_Fijos y Gastos_Variables en la columna del mes. 5) Revisa Resumen, IVA y PPM. El F29 del mes se declara al mes siguiente.
B10: IVA (19%)
B11: El IVA no es un gasto de la automotora: es un impuesto que cobras y pagas. • IVA débito: el IVA de tus ventas y servicios (autos vendidos, taller, repuestos, comisiones). • IVA crédito: el IVA de tus compras afectas (autos con factura, insumos, publicidad, luz, etc.). • IVA a pagar = débito − crédito − remanente del mes anterior. Si da negativo, queda remanente. Importante: si compras un usado a un particular, casi nunca hay crédito fiscal. Marca Compra afecta IVA = No.
B13: PPM (Pagos Provisionales Mensuales)
B14: El PPM se calcula sobre los ingresos netos del mes (sin IVA), no sobre la utilidad. Aunque un mes salgas a pérdida, igual puede corresponder PPM. La tasa vive en Configuracion. Si es el primer año comercial suele usarse 0,25%. Después el SII fija un factor según el año anterior. Confírmala con tu contador. El PPM se imputa al impuesto a la renta de primera categoría al cierre del año.
B16: Consignación vs. venta propia
B17: • Auto propio (Nuevo o Usado): el ingreso es el precio de venta. El costo es lo que te costó. La utilidad de la unidad es venta neta − costo neto − comisión del vendedor. • Consignación: el auto no es tuyo. El ingreso de la automotora es la comisión. Llena Comisión consignación (con IVA) y deja el costo en 0.
B19: Pasar a Google Sheets
B20: 1. Sube este archivo a Google Drive. 2. Clic derecho → Abrir con → Google Sheets. 3. Archivo → Guardar como Google Sheets (así queda nativo y se puede compartir). Las fórmulas están en formato compatible (SUMIFS, INDEX, IF). No uses macros.
... B25: Las filas de ejemplo en agosto 2026 se pueden borrar. No borres columnas ni encabezados.

Sheet Configuracion
A1: Configuración
A2: Cambia solo las celdas amarillas. El resto de la planilla toma estos valores.
A4: DATOS DE LA EMPRESA
A5: Nombre de la automotora | B5: Mi Automotora | C5: Aparece en el resumen y en las impresiones.
A6: RUT | B6: 76.000.000-K | C6: Solo referencia; no se usa en fórmulas.
A7: Año de trabajo | B7: 2026 | C7: Filtra ventas, IVA y PPM. Cámbialo en enero.
A8: Mes de trabajo (1 a 12) | B8: 8 | C8: El Resumen, IVA y PPM muestran este mes. 8 = agosto.
A10: TASAS TRIBUTARIAS
A11: Tasa IVA | B11: 0.19 | C11: Chile: 19%. No la cambies salvo cambio legal.
A12: Tasa PPM | B12: 0.0025 | C12: Por defecto 0,25% (primer año). Reemplázala por el factor del SII.
A13: Tasa impuesto 1ª categoría | B13: 0.27 | C13: 27% régimen general. PyME 14 D puede ser 25%. Confirma con tu contador.
A15: MES EN CURSO (se calcula solo)
A16: Nombre del mes | B16: =CHOOSE(B8,"Enero","Febrero","Marzo","Abril","Mayo","Junio","Julio","Agosto","Septiembre","Octubre","Noviembre","Diciembre") | C16: Lo usa el Resumen como título del período.
A18: LEYENDA
A19: Celda de entrada | B19: Dato que tú escribes
A20: Celda calculada | B20: ="Cálculo automático"
A22: Notas para el contador | B22: Tasa PPM confirmada con contador: _ / Régimen: _
A26: Los movimientos de agosto 2026 son EJEMPLOS (pocas ventas y una nómina completa, por eso el mes puede salir a pérdida). Bórralos y carga tus datos reales. Cambia el nombre de la automotora arriba.

Sheet Resumen
A1: Resumen de gestión
A2: =Configuracion!$B$5 & " · " & Configuracion!B16 & " " & Configuracion!$B$7 & " · Cifras netas, sin IVA"
A4: INGRESOS DEL MES | D4: MARGEN BRUTO | G4: UTILIDAD OPERACIONAL | J4: UTILIDAD NETA EST.
A5: =INDEX(Estado_Resultados!$B$13:$M$13,1,Configuracion!$B$8) | D5: =INDEX(Estado_Resultados!$B$19:$M$19,1,Configuracion!$B$8) | G5: =INDEX(Estado_Resultados!$B$27:$M$27,1,Configuracion!$B$8) | J5: =INDEX(Estado_Resultados!$B$32:$M$32,1,Configuracion!$B$8)
A6: ="Mes en curso" | D6: =IF(INDEX(Estado_Resultados!$B$13:$M$13,1,Configuracion!$B$8)=0,"",TEXT(INDEX(Estado_Resultados!$B$20:$M$20,1,Configuracion!$B$8),"0.0%")&" sobre ventas") | G6: =IF(INDEX(Estado_Resultados!$B$27:$M$27,1,Configuracion!$B$8)>=0,"La operación gana","La operación pierde") | J6: ="Después de provisión 1ª cat."
A8: De dónde sale la plata este mes | H8: Qué hay que pagar al SII este mes (F29)
A9: Línea | B9: Monto neto | C9: % de ingresos | H9: Concepto | I9: Monto
A10: Autos nuevos | B10: =INDEX(Estado_Resultados!$B$7:$M$7,1,Configuracion!$B$8) | C10: =IF(INDEX(Estado_Resultados!$B$13:$M$13,1,Configuracion!$B$8)=0,"",B10/INDEX(Estado_Resultados!$B$13:$M$13,1,Configuracion!$B$8)) | H10: IVA débito | I10: =INDEX(IVA!$B$10:$M$10,1,Configuracion!$B$8)
A11: Autos usados | B11: =INDEX(Estado_Resultados!$B$8:$M$8,1,Configuracion!$B$8) | C11: =IF(INDEX(Estado_Resultados!$B$13:$M$13,1,Configuracion!$B$8)=0,"",B11/INDEX(Estado_Resultados!$B$13:$M$13,1,Configuracion!$B$8)) | H11: IVA crédito | I11: =INDEX(IVA!$B$17:$M$17,1,Configuracion!$B$8)
A12: Consignación (comisiones) | B12: =INDEX(Estado_Resultados!$B$9:$M$9,1,Configuracion!$B$8) | C12: =IF(INDEX(Estado_Resultados!$B$13:$M$13,1,Configuracion!$B$8)=0,"",B12/INDEX(Estado_Resultados!$B$13:$M$13,1,Configuracion!$B$8)) | H12: IVA determinado | I12: =INDEX(IVA!$B$19:$M$19,1,Configuracion!$B$8)
A13: Taller | B13: =INDEX(Estado_Resultados!$B$10:$M$10,1,Configuracion!$B$8) | C13: =IF(INDEX(Estado_Resultados!$B$13:$M$13,1,Configuracion!$B$8)=0,"",B13/INDEX(Estado_Resultados!$B$13:$M$13,1,Configuracion!$B$8)) | H13: Remanente anterior | I13: =INDEX(IVA!$B$20:$M$20,1,Configuracion!$B$8)
A14: Repuestos | B14: =INDEX(Estado_Resultados!$B$11:$M$11,1,Configuracion!$B$8) | C14: =IF(INDEX(Estado_Resultados!$B$13:$M$13,1,Configuracion!$B$8)=0,"",B14/INDEX(Estado_Resultados!$B$13:$M$13,1,Configuracion!$B$8)) | H14: IVA A PAGAR | I14: =INDEX(IVA!$B$21:$M$21,1,Configuracion!$B$8)
A15: Otros ingresos | B15: =INDEX(Estado_Resultados!$B$12:$M$12,1,Configuracion!$B$8) | C15: =IF(INDEX(Estado_Resultados!$B$13:$M$13,1,Configuracion!$B$8)=0,"",B15/INDEX(Estado_Resultados!$B$13:$M$13,1,Configuracion!$B$8)) | H15: PPM A PAGAR | I15: =INDEX(PPM!$B$8:$M$8,1,Configuracion!$B$8)
A16: TOTAL INGRESOS | B16: =INDEX(Estado_Resultados!$B$13:$M$13,1,Configuracion!$B$8) | C16: =IF(INDEX(Estado_Resultados!$B$13:$M$13,1,Configuracion!$B$8)=0,"",B16/INDEX(Estado_Resultados!$B$13:$M$13,1,Configuracion!$B$8)) | H16: TOTAL F29 (IVA + PPM) | I16: =I14+I15
A18: Costo de autos vendidos | B18: =INDEX(Estado_Resultados!$B$16:$M$16,1,Configuracion!$B$8) | C18: =IF(INDEX(Estado_Resultados!$B$13:$M$13,1,Configuracion!$B$8)=0,"",B18/INDEX(Estado_Resultados!$B$13:$M$13,1,Configuracion!$B$8)) | H18: ="Declarar en el F29 de "&TEXT(DATE(Configuracion!$B$7,Configuracion!$B$8,1)+32-DAY(DATE(Configuracion!$B$7,Configuracion!$B$8,1)+32),"MMMM YYYY")&". Fecha habitual: día 12 del mes siguiente (o hábil siguiente)."
A19: Costo taller y repuestos | B19: =INDEX(Estado_Resultados!$B$17:$M$17,1,Configuracion!$B$8) | C19: =IF(INDEX(Estado_Resultados!$B$13:$M$13,1,Configuracion!$B$8)=0,"",B19/INDEX(Estado_Resultados!$B$13:$M$13,1,Configuracion!$B$8))
A20: MARGEN BRUTO | B20: =INDEX(Estado_Resultados!$B$19:$M$19,1,Configuracion!$B$8) | C20: =IF(INDEX(Estado_Resultados!$B$13:$M$13,1,Configuracion!$B$8)=0,"",B20/INDEX(Estado_Resultados!$B$13:$M$13,1,Configuracion!$B$8))
A22: Gastos fijos | B22: =INDEX(Estado_Resultados!$B$23:$M$23,1,Configuracion!$B$8) | C22: =IF(INDEX(Estado_Resultados!$B$13:$M$13,1,Configuracion!$B$8)=0,"",B22/INDEX(Estado_Resultados!$B$13:$M$13,1,Configuracion!$B$8))
A23: Comisiones de vendedores | B23: =INDEX(Estado_Resultados!$B$24:$M$24,1,Configuracion!$B$8) | C23: =IF(INDEX(Estado_Resultados!$B$13:$M$13,1,Configuracion!$B$8)=0,"",B23/INDEX(Estado_Resultados!$B$13:$M$13,1,Configuracion!$B$8))
A24: Gastos variables | B24: =INDEX(Estado_Resultados!$B$25:$M$25,1,Configuracion!$B$8) | C24: =IF(INDEX(Estado_Resultados!$B$13:$M$13,1,Configuracion!$B$8)=0,"",B24/INDEX(Estado_Resultados!$B$13:$M$13,1,Configuracion!$B$8))
A25: TOTAL GASTOS | B25: =INDEX(Estado_Resultados!$B$26:$M$26,1,Configuracion!$B$8) | C25: =IF(INDEX(Estado_Resultados!$B$13:$M$13,1,Configuracion!$B$8)=0,"",B25/INDEX(Estado_Resultados!$B$13:$M$13,1,Configuracion!$B$8))
A27: UTILIDAD OPERACIONAL | B27: =INDEX(Estado_Resultados!$B$27:$M$27,1,Configuracion!$B$8) | C27: =IF(INDEX(Estado_Resultados!$B$13:$M$13,1,Configuracion!$B$8)=0,"",B27/INDEX(Estado_Resultados!$B$13:$M$13,1,Configuracion!$B$8))
A28: Provisión impuesto renta | B28: =INDEX(Estado_Resultados!$B$31:$M$31,1,Configuracion!$B$8) | C28: =IF(INDEX(Estado_Resultados!$B$13:$M$13,1,Configuracion!$B$8)=0,"",B28/INDEX(Estado_Resultados!$B$13:$M$13,1,Configuracion!$B$8))
A29: UTILIDAD NETA ESTIMADA | B29: =INDEX(Estado_Resultados!$B$32:$M$32,1,Configuracion!$B$8) | C29: =IF(INDEX(Estado_Resultados!$B$13:$M$13,1,Configuracion!$B$8)=0,"",B29/INDEX(Estado_Resultados!$B$13:$M$13,1,Configuracion!$B$8))
A31: Acumulado del año | H31: Lectura rápida
A32: Indicador | B32: Acumulado hasta el mes en curso | C32: Proyección año (suma 12 meses) | H32: =IF(INDEX(Estado_Resultados!$B$13:$M$13,1,Configuracion!$B$8)=0,"Carga ventas o elige un mes con movimiento.",IF(INDEX(Estado_Resultados!$B$27:$M$27,1,Configuracion!$B$8)>=0,"Este mes la automotora gana "&TEXT(INDEX(Estado_Resultados!$B$27:$M$27,1,Configuracion!$B$8),"$#,##0")&" a nivel operacional. "&"El F29 estimado (IVA + PPM) es "&TEXT(I16,"$#,##0")&".","Este mes la operación pierde "&TEXT(-(INDEX(Estado_Resultados!$B$27:$M$27,1,Configuracion!$B$8)),"$#,##0")&". "&"Revisa gastos fijos y el margen por auto. El F29 igual puede corresponder: "&TEXT(I16,"$#,##0")&"."))
A33: Ingresos | B33: =SUM(OFFSET(Estado_Resultados!$B$13,0,0,1,Configuracion!$B$8)) | C33: =Estado_Resultados!N13
A34: Margen bruto | B34: =SUM(OFFSET(Estado_Resultados!$B$19,0,0,1,Configuracion!$B$8)) | C34: =Estado_Resultados!N19
A35: Utilidad operacional | B35: =SUM(OFFSET(Estado_Resultados!$B$27,0,0,1,Configuracion!$B$8)) | C35: =Estado_Resultados!N27
A36: Utilidad neta estimada | B36: =SUM(OFFSET(Estado_Resultados!$B$32,0,0,1,Configuracion!$B$8)) | C36: =Estado_Resultados!N32
A37: IVA pagado / a pagar | B37: =SUM(OFFSET(IVA!$B$21,0,0,1,Configuracion!$B$8)) | C37: =IVA!N21
A38: PPM pagado / a pagar | B38: =SUM(OFFSET(PPM!$B$8,0,0,1,Configuracion!$B$8)) | C38: =PPM!N8

Sheet Estado_Resultados
A1: Estado de resultados — 12 meses
A2: Motor de cálculo. No edites esta hoja: se alimenta de las cargas. Cifras NETAS, sin IVA.
A3: Año de las cifras | B3: =Configuracion!$B$7 | C3: Todas las columnas de esta hoja son fórmulas. Los datos se cargan en las otras pestañas.
A4: Concepto | B4: Enero | C4: Febrero | D4: Marzo | E4: Abril | F4: Mayo | G4: Junio | H4: Julio | I4: Agosto | J4: Septiembre | K4: Octubre | L4: Noviembre | M4: Diciembre | N4: Total año
A6: INGRESOS
A7: Autos nuevos | B7: =SUMIFS(Ventas_Autos!$W$6:$W$205,Ventas_Autos!$D$6:$D$205,"Nuevo",Ventas_Autos!$U$6:$U$205,Configuracion!$B$7,Ventas_Autos!$V$6:$V$205,1,Ventas_Autos!$Q$6:$Q$205,"Vendido") | C7: =SUMIFS(Ventas_Autos!$W$6:$W$205,Ventas_Autos!$D$6:$D$205,"Nuevo",Ventas_Autos!$U$6:$U$205,Configuracion!$B$7,Ventas_Autos!$V$6:$V$205,2,Ventas_Autos!$Q$6:$Q$205,"Vendido") | D7: =SUMIFS(Ventas_Autos!$W$6:$W$205,Ventas_Autos!$D$6:$D$205,"Nuevo",Ventas_Autos!$U$6:$U$205,Configuracion!$B$7,Ventas_Autos!$V$6:$V$205,3,Ventas_Autos!$Q$6:$Q$205,"Vendido") | E7: =SUMIFS(Ventas_Autos!$W$6:$W$205,Ventas_Autos!$D$6:$D$205,"Nuevo",Ventas_Autos!$U$6:$U$205,Configuracion!$B$7,Ventas_Autos!$V$6:$V$205,4,Ventas_Autos!$Q$6:$Q$205,"Vendido") | F7: =SUMIFS(Ventas_Autos!$W$6:$W$205,Ventas_Autos!$D$6:$D$205,"Nuevo",Ventas_Autos!$U$6:$U$205,Configuracion!$B$7,Ventas_Autos!$V$6:$V$205,5,Ventas_Autos!$Q$6:$Q$205,"Vendido") | G7: =SUMIFS(Ventas_Autos!$W$6:$W$205,Ventas_Autos!$D$6:$D$205,"Nuevo",Ventas_Autos!$U$6:$U$205,Configuracion!$B$7,Ventas_Autos!$V$6:$V$205,6,Ventas_Autos!$Q$6:$Q$205,"Vendido") | H7: =SUMIFS(Ventas_Autos!$W$6:$W$205,Ventas_Autos!$D$6:$D$205,"Nuevo",Ventas_Autos!$U$6:$U$205,Configuracion!$B$7,Ventas_Autos!$V$6:$V$205,7,Ventas_Autos!$Q$6:$Q$205,"Vendido") | I7: =SUMIFS(Ventas_Autos!$W$6:$W$205,Ventas_Autos!$D$6:$D$205,"Nuevo",Ventas_Autos!$U$6:$U$205,Configuracion!$B$7,Ventas_Autos!$V$6:$V$205,8,Ventas_Autos!$Q$6:$Q$205,"Vendido") | J7: =SUMIFS(Ventas_Autos!$W$6:$W$205,Ventas_Autos!$D$6:$D$205,"Nuevo",Ventas_Autos!$U$6:$U$205,Configuracion!$B$7,Ventas_Autos!$V$6:$V$205,9,Ventas_Autos!$Q$6:$Q$205,"Vendido") | K7: =SUMIFS(Ventas_Autos!$W$6:$W$205,Ventas_Autos!$D$6:$D$205,"Nuevo",Ventas_Autos!$U$6:$U$205,Configuracion!$B$7,Ventas_Autos!$V$6:$V$205,10,Ventas_Autos!$Q$6:$Q$205,"Vendido") | L7: =SUMIFS(Ventas_Autos!$W$6:$W$205,Ventas_Autos!$D$6:$D$205,"Nuevo",Ventas_Autos!$U$6:$U$205,Configuracion!$B$7,Ventas_Autos!$V$6:$V$205,11,Ventas_Autos!$Q$6:$Q$205,"Vendido") | M7: =SUMIFS(Ventas_Autos!$W$6:$W$205,Ventas_Autos!$D$6:$D$205,"Nuevo",Ventas_Autos!$U$6:$U$205,Configuracion!$B$7,Ventas_Autos!$V$6:$V$205,12,Ventas_Autos!$Q$6:$Q$205,"Vendido") | N7: =SUM(B7:M7)
A8: Autos usados | B8: =SUMIFS(Ventas_Autos!$W$6:$W$205,Ventas_Autos!$D$6:$D$205,"Usado",Ventas_Autos!$U$6:$U$205,Configuracion!$B$7,Ventas_Autos!$V$6:$V$205,1,Ventas_Autos!$Q$6:$Q$205,"Vendido") | C8: =SUMIFS(Ventas_Autos!$W$6:$W$205,Ventas_Autos!$D$6:$D$205,"Usado",Ventas_Autos!$U$6:$U$205,Configuracion!$B$7,Ventas_Autos!$V$6:$V$205,2,Ventas_Autos!$Q$6:$Q$205,"Vendido") | D8: =SUMIFS(Ventas_Autos!$W$6:$W$205,Ventas_Autos!$D$6:$D$205,"Usado",Ventas_Autos!$U$6:$U$205,Configuracion!$B$7,Ventas_Autos!$V$6:$V$205,3,Ventas_Autos!$Q$6:$Q$205,"Vendido") | E8: =SUMIFS(Ventas_Autos!$W$6:$W$205,Ventas_Autos!$D$6:$D$205,"Usado",Ventas_Autos!$U$6:$U$205,Configuracion!$B$7,Ventas_Autos!$V$6:$V$205,4,Ventas_Autos!$Q$6:$Q$205,"Vendido") | F8: =SUMIFS(Ventas_Autos!$W$6:$W$205,Ventas_Autos!$D$6:$D$205,"Usado",Ventas_Autos!$U$6:$U$205,Configuracion!$B$7,Ventas_Autos!$V$6:$V$205,5,Ventas_Autos!$Q$6:$Q$205,"Vendido") | G8: =SUMIFS(Ventas_Autos!$W$6:$W$205,Ventas_Autos!$D$6:$D$205,"Usado",Ventas_Autos!$U$6:$U$205,Configuracion!$B$7,Ventas_Autos!$V$6:$V$205,6,Ventas_Autos!$Q$6:$Q$205,"Vendido") | H8: =SUMIFS(Ventas_Autos!$W$6:$W$205,Ventas_Autos!$D$6:$D$205,"Usado",Ventas_Autos!$U$6:$U$205,Configuracion!$B$7,Ventas_Autos!$V$6:$V$205,7,Ventas_Autos!$Q$6:$Q$205,"Vendido") | I8: =SUMIFS(Ventas_Autos!$W$6:$W$205,Ventas_Autos!$D$6:$D$205,"Usado",Ventas_Autos!$U$6:$U$205,Configuracion!$B$7,Ventas_Autos!$V$6:$V$205,8,Ventas_Autos!$Q$6:$Q$205,"Vendido") | J8: =SUMIFS(Ventas_Autos!$W$6:$W$205,Ventas_Autos!$D$6:$D$205,"Usado",Ventas_Autos!$U$6:$U$205,Configuracion!$B$7,Ventas_Autos!$V$6:$V$205,9,Ventas_Autos!$Q$6:$Q$205,"Vendido") | K8: =SUMIFS(Ventas_Autos!$W$6:$W$205,Ventas_Autos!$D$6:$D$205,"Usado",Ventas_Autos!$U$6:$U$205,Configuracion!$B$7,Ventas_Autos!$V$6:$V$205,10,Ventas_Autos!$Q$6:$Q$205,"Vendido") | L8: =SUMIFS(Ventas_Autos!$W$6:$W$205,Ventas_Autos!$D$6:$D$205,"Usado",Ventas_Autos!$U$6:$U$205,Configuracion!$B$7,Ventas_Autos!$V$6:$V$205,11,Ventas_Autos!$Q$6:$Q$205,"Vendido") | M8: =SUMIFS(Ventas_Autos!$W$6:$W$205,Ventas_Autos!$D$6:$D$205,"Usado",Ventas_Autos!$U$6:$U$205,Configuracion!$B$7,Ventas_Autos!$V$6:$V$205,12,Ventas_Autos!$Q$6:$Q$205,"Vendido") | N8: =SUM(B8:M8)
A9: Comisiones por consignación | B9: =SUMIFS(Ventas_Autos!$W$6:$W$205,Ventas_Autos!$D$6:$D$205,"Consignación",Ventas_Autos!$U$6:$U$205,Configuracion!$B$7,Ventas_Autos!$V$6:$V$205,1,Ventas_Autos!$Q$6:$Q$205,"Vendido") | C9: =SUMIFS(Ventas_Autos!$W$6:$W$205,Ventas_Autos!$D$6:$D$205,"Consignación",Ventas_Autos!$U$6:$U$205,Configuracion!$B$7,Ventas_Autos!$V$6:$V$205,2,Ventas_Autos!$Q$6:$Q$205,"Vendido") | D9: =SUMIFS(Ventas_Autos!$W$6:$W$205,Ventas_Autos!$D$6:$D$205,"Consignación",Ventas_Autos!$U$6:$U$205,Configuracion!$B$7,Ventas_Autos!$V$6:$V$205,3,Ventas_Autos!$Q$6:$Q$205,"Vendido") | E9: =SUMIFS(Ventas_Autos!$W$6:$W$205,Ventas_Autos!$D$6:$D$205,"Consignación",Ventas_Autos!$U$6:$U$205,Configuracion!$B$7,Ventas_Autos!$V$6:$V$205,4,Ventas_Autos!$Q$6:$Q$205,"Vendido") | F9: =SUMIFS(Ventas_Autos!$W$6:$W$205,Ventas_Autos!$D$6:$D$205,"Consignación",Ventas_Autos!$U$6:$U$205,Configuracion!$B$7,Ventas_Autos!$V$6:$V$205,5,Ventas_Autos!$Q$6:$Q$205,"Vendido") | G9: =SUMIFS(Ventas_Autos!$W$6:$W$205,Ventas_Autos!$D$6:$D$205,"Consignación",Ventas_Autos!$U$6:$U$205,Configuracion!$B$7,Ventas_Autos!$V$6:$V$205,6,Ventas_Autos!$Q$6:$Q$205,"Vendido") | H9: =SUMIFS(Ventas_Autos!$W$6:$W$205,Ventas_Autos!$D$6:$D$205,"Consignación",Ventas_Autos!$U$6:$U$205,Configuracion!$B$7,Ventas_Autos!$V$6:$V$205,7,Ventas_Autos!$Q$6:$Q$205,"Vendido") | I9: =SUMIFS(Ventas_Autos!$W$6:$W$205,Ventas_Autos!$D$6:$D$205,"Consignación",Ventas_Autos!$U$6:$U$205,Configuracion!$B$7,Ventas_Autos!$V$6:$V$205,8,Ventas_Autos!$Q$6:$Q$205,"Vendido") | J9: =SUMIFS(Ventas_Autos!$W$6:$W$205,Ventas_Autos!$D$6:$D$205,"Consignación",Ventas_Autos!$U$6:$U$205,Configuracion!$B$7,Ventas_Autos!$V$6:$V$205,9,Ventas_Autos!$Q$6:$Q$205,"Vendido") | K9: =SUMIFS(Ventas_Autos!$W$6:$W$205,Ventas_Autos!$D$6:$D$205,"Consignación",Ventas_Autos!$U$6:$U$205,Configuracion!$B$7,Ventas_Autos!$V$6:$V$205,10,Ventas_Autos!$Q$6:$Q$205,"Vendido") | L9: =SUMIFS(Ventas_Autos!$W$6:$W$205,Ventas_Autos!$D$6:$D$205,"Consignación",Ventas_Autos!$U$6:$U$205,Configuracion!$B$7,Ventas_Autos!$V$6:$V$205,11,Ventas_Autos!$Q$6:$Q$205,"Vendido") | M9: =SUMIFS(Ventas_Autos!$W$6:$W$205,Ventas_Autos!$D$6:$D$205,"Consignación",Ventas_Autos!$U$6:$U$205,Configuracion!$B$7,Ventas_Autos!$V$6:$V$205,12,Ventas_Autos!$Q$6:$Q$205,"Vendido") | N9: =SUM(B9:M9)
A10: Taller (mano de obra) | B10: =SUMIFS(Taller_Repuestos!$F$6:$F$205,Taller_Repuestos!$B$6:$B$205,"Taller",Taller_Repuestos!$M$6:$M$205,Configuracion!$B$7,Taller_Repuestos!$N$6:$N$205,1) | C10: =SUMIFS(Taller_Repuestos!$F$6:$F$205,Taller_Repuestos!$B$6:$B$205,"Taller",Taller_Repuestos!$M$6:$M$205,Configuracion!$B$7,Taller_Repuestos!$N$6:$N$205,2) | D10: =SUMIFS(Taller_Repuestos!$F$6:$F$205,Taller_Repuestos!$B$6:$B$205,"Taller",Taller_Repuestos!$M$6:$M$205,Configuracion!$B$7,Taller_Repuestos!$N$6:$N$205,3) | E10: =SUMIFS(Taller_Repuestos!$F$6:$F$205,Taller_Repuestos!$B$6:$B$205,"Taller",Taller_Repuestos!$M$6:$M$205,Configuracion!$B$7,Taller_Repuestos!$N$6:$N$205,4) | F10: =SUMIFS(Taller_Repuestos!$F$6:$F$205,Taller_Repuestos!$B$6:$B$205,"Taller",Taller_Repuestos!$M$6:$M$205,Configuracion!$B$7,Taller_Repuestos!$N$6:$N$205,5) | G10: =SUMIFS(Taller_Repuestos!$F$6:$F$205,Taller_Repuestos!$B$6:$B$205,"Taller",Taller_Repuestos!$M$6:$M$205,Configuracion!$B$7,Taller_Repuestos!$N$6:$N$205,6) | H10: =SUMIFS(Taller_Repuestos!$F$6:$F$205,Taller_Repuestos!$B$6:$B$205,"Taller",Taller_Repuestos!$M$6:$M$205,Configuracion!$B$7,Taller_Repuestos!$N$6:$N$205,7) | I10: =SUMIFS(Taller_Repuestos!$F$6:$F$205,Taller_Repuestos!$B$6:$B$205,"Taller",Taller_Repuestos!$M$6:$M$205,Configuracion!$B$7,Taller_Repuestos!$N$6:$N$205,8) | J10: =SUMIFS(Taller_Repuestos!$F$6:$F$205,Taller_Repuestos!$B$6:$B$205,"Taller",Taller_Repuestos!$M$6:$M$205,Configuracion!$B$7,Taller_Repuestos!$N$6:$N$205,9) | K10: =SUMIFS(Taller_Repuestos!$F$6:$F$205,Taller_Repuestos!$B$6:$B$205,"Taller",Taller_Repuestos!$M$6:$M$205,Configuracion!$B$7,Taller_Repuestos!$N$6:$N$205,10) | L10: =SUMIFS(Taller_Repuestos!$F$6:$F$205,Taller_Repuestos!$B$6:$B$205,"Taller",Taller_Repuestos!$M$6:$M$205,Configuracion!$B$7,Taller_Repuestos!$N$6:$N$205,11) | M10: =SUMIFS(Taller_Repuestos!$F$6:$F$205,Taller_Repuestos!$B$6:$B$205,"Taller",Taller_Repuestos!$M$6:$M$205,Configuracion!$B$7,Taller_Repuestos!$N$6:$N$205,12) | N10: =SUM(B10:M10)
A11: Repuestos | B11: =SUMIFS(Taller_Repuestos!$F$6:$F$205,Taller_Repuestos!$B$6:$B$205,"Repuestos",Taller_Repuestos!$M$6:$M$205,Configuracion!$B$7,Taller_Repuestos!$N$6:$N$205,1) | C11: =SUMIFS(Taller_Repuestos!$F$6:$F$205,Taller_Repuestos!$B$6:$B$205,"Repuestos",Taller_Repuestos!$M$6:$M$205,Configuracion!$B$7,Taller_Repuestos!$N$6:$N$205,2) | D11: =SUMIFS(Taller_Repuestos!$F$6:$F$205,Taller_Repuestos!$B$6:$B$205,"Repuestos",Taller_Repuestos!$M$6:$M$205,Configuracion!$B$7,Taller_Repuestos!$N$6:$N$205,3) | E11: =SUMIFS(Taller_Repuestos!$F$6:$F$205,Taller_Repuestos!$B$6:$B$205,"Repuestos",Taller_Repuestos!$M$6:$M$205,Configuracion!$B$7,Taller_Repuestos!$N$6:$N$205,4) | F11: =SUMIFS(Taller_Repuestos!$F$6:$F$205,Taller_Repuestos!$B$6:$B$205,"Repuestos",Taller_Repuestos!$M$6:$M$205,Configuracion!$B$7,Taller_Repuestos!$N$6:$N$205,5) | G11: =SUMIFS(Taller_Repuestos!$F$6:$F$205,Taller_Repuestos!$B$6:$B$205,"Repuestos",Taller_Repuestos!$M$6:$M$205,Configuracion!$B$7,Taller_Repuestos!$N$6:$N$205,6) | H11: =SUMIFS(Taller_Repuestos!$F$6:$F$205,Taller_Repuestos!$B$6:$B$205,"Repuestos",Taller_Repuestos!$M$6:$M$205,Configuracion!$B$7,Taller_Repuestos!$N$6:$N$205,7) | I11: =SUMIFS(Taller_Repuestos!$F$6:$F$205,Taller_Repuestos!$B$6:$B$205,"Repuestos",Taller_Repuestos!$M$6:$M$205,Configuracion!$B$7,Taller_Repuestos!$N$6:$N$205,8) | J11: =SUMIFS(Taller_Repuestos!$F$6:$F$205,Taller_Repuestos!$B$6:$B$205,"Repuestos",Taller_Repuestos!$M$6:$M$205,Configuracion!$B$7,Taller_Repuestos!$N$6:$N$205,9) | K11: =SUMIFS(Taller_Repuestos!$F$6:$F$205,Taller_Repuestos!$B$6:$B$205,"Repuestos",Taller_Repuestos!$M$6:$M$205,Configuracion!$B$7,Taller_Repuestos!$N$6:$N$205,10) | L11: =SUMIFS(Taller_Repuestos!$F$6:$F$205,Taller_Repuestos!$B$6:$B$205,"Repuestos",Taller_Repuestos!$M$6:$M$205,Configuracion!$B$7,Taller_Repuestos!$N$6:$N$205,11) | M11: =SUMIFS(Taller_Repuestos!$F$6:$F$205,Taller_Repuestos!$B$6:$B$205,"Repuestos",Taller_Repuestos!$M$6:$M$205,Configuracion!$B$7,Taller_Repuestos!$N$6:$N$205,12) | N11: =SUM(B11:M11)
A12: Otros ingresos | B12: =SUMIFS(Otros_Ingresos!$D$6:$D$105,Otros_Ingresos!$H$6:$H$105,Configuracion!$B$7,Otros_Ingresos!$I$6:$I$105,1) | C12: =SUMIFS(Otros_Ingresos!$D$6:$D$105,Otros_Ingresos!$H$6:$H$105,Configuracion!$B$7,Otros_Ingresos!$I$6:$I$105,2) | D12: =SUMIFS(Otros_Ingresos!$D$6:$D$105,Otros_Ingresos!$H$6:$H$105,Configuracion!$B$7,Otros_Ingresos!$I$6:$I$105,3) | E12: =SUMIFS(Otros_Ingresos!$D$6:$D$105,Otros_Ingresos!$H$6:$H$105,Configuracion!$B$7,Otros_Ingresos!$I$6:$I$105,4) | F12: =SUMIFS(Otros_Ingresos!$D$6:$D$105,Otros_Ingresos!$H$6:$H$105,Configuracion!$B$7,Otros_Ingresos!$I$6:$I$105,5) | G12: =SUMIFS(Otros_Ingresos!$D$6:$D$105,Otros_Ingresos!$H$6:$H$105,Configuracion!$B$7,Otros_Ingresos!$I$6:$I$105,6) | H12: =SUMIFS(Otros_Ingresos!$D$6:$D$105,Otros_Ingresos!$H$6:$H$105,Configuracion!$B$7,Otros_Ingresos!$I$6:$I$105,7) | I12: =SUMIFS(Otros_Ingresos!$D$6:$D$105,Otros_Ingresos!$H$6:$H$105,Configuracion!$B$7,Otros_Ingresos!$I$6:$I$105,8) | J12: =SUMIFS(Otros_Ingresos!$D$6:$D$105,Otros_Ingresos!$H$6:$H$105,Configuracion!$B$7,Otros_Ingresos!$I$6:$I$105,9) | K12: =SUMIFS(Otros_Ingresos!$D$6:$D$105,Otros_Ingresos!$H$6:$H$105,Configuracion!$B$7,Otros_Ingresos!$I$6:$I$105,10) | L12: =SUMIFS(Otros_Ingresos!$D$6:$D$105,Otros_Ingresos!$H$6:$H$105,Configuracion!$B$7,Otros_Ingresos!$I$6:$I$105,11) | M12: =SUMIFS(Otros_Ingresos!$D$6:$D$105,Otros_Ingresos!$H$6:$H$105,Configuracion!$B$7,Otros_Ingresos!$I$6:$I$105,12) | N12: =SUM(B12:M12)
A13: TOTAL INGRESOS | B13: =B7+B8+B9+B10+B11+B12 | C13: =C7+C8+C9+C10+C11+C12 | D13: =D7+D8+D9+D10+D11+D12 | E13: =E7+E8+E9+E10+E11+E12 | F13: =F7+F8+F9+F10+F11+F12 | G13: =G7+G8+G9+G10+G11+G12 | H13: =H7+H8+H9+H10+H11+H12 | I13: =I7+I8+I9+I10+I11+I12 | ... M13: =M7+M8+M9+M10+M11+M12 | N13: =SUM(B13:M13)
A15: COSTOS DIRECTOS
A16: Costo de autos vendidos | B16: =SUMIFS(Ventas_Autos!$Y$6:$Y$205,Ventas_Autos!$U$6:$U$205,Configuracion!$B$7,Ventas_Autos!$V$6:$V$205,1,Ventas_Autos!$Q$6:$Q$205,"Vendido") | C16: =SUMIFS(Ventas_Autos!$Y$6:$Y$205,Ventas_Autos!$U$6:$U$205,Configuracion!$B$7,Ventas_Autos!$V$6:$V$205,2,Ventas_Autos!$Q$6:$Q$205,"Vendido") | D16: =SUMIFS(Ventas_Autos!$Y$6:$Y$205,Ventas_Autos!$U$6:$U$205,Configuracion!$B$7,Ventas_Autos!$V$6:$V$205,3,Ventas_Autos!$Q$6:$Q$205,"Vendido") | E16: =SUMIFS(Ventas_Autos!$Y$6:$Y$205,Ventas_Autos!$U$6:$U$205,Configuracion!$B$7,Ventas_Autos!$V$6:$V$205,4,Ventas_Autos!$Q$6:$Q$205,"Vendido") | F16: =SUMIFS(Ventas_Autos!$Y$6:$Y$205,Ventas_Autos!$U$6:$U$205,Configuracion!$B$7,Ventas_Autos!$V$6:$V$205,5,Ventas_Autos!$Q$6:$Q$205,"Vendido") | G16: =SUMIFS(Ventas_Autos!$Y$6:$Y$205,Ventas_Autos!$U$6:$U$205,Configuracion!$B$7,Ventas_Autos!$V$6:$V$205,6,Ventas_Autos!$Q$6:$Q$205,"Vendido") | H16: =SUMIFS(Ventas_Autos!$Y$6:$Y$205,Ventas_Autos!$U$6:$U$205,Configuracion!$B$7,Ventas_Autos!$V$6:$V$205,7,Ventas_Autos!$Q$6:$Q$205,"Vendido") | I16: =SUMIFS(Ventas_Autos!$Y$6:$Y$205,Ventas_Autos!$U$6:$U$205,Configuracion!$B$7,Ventas_Autos!$V$6:$V$205,8,Ventas_Autos!$Q$6:$Q$205,"Vendido") | J16: =SUMIFS(Ventas_Autos!$Y$6:$Y$205,Ventas_Autos!$U$6:$U$205,Configuracion!$B$7,Ventas_Autos!$V$6:$V$205,9,Ventas_Autos!$Q$6:$Q$205,"Vendido") | K16: =SUMIFS(Ventas_Autos!$Y$6:$Y$205,Ventas_Autos!$U$6:$U$205,Configuracion!$B$7,Ventas_Autos!$V$6:$V$205,10,Ventas_Autos!$Q$6:$Q$205,"Vendido") | L16: =SUMIFS(Ventas_Autos!$Y$6:$Y$205,Ventas_Autos!$U$6:$U$205,Configuracion!$B$7,Ventas_Autos!$V$6:$V$205,11,Ventas_Autos!$Q$6:$Q$205,"Vendido") | M16: =SUMIFS(Ventas_Autos!$Y$6:$Y$205,Ventas_Autos!$U$6:$U$205,Configuracion!$B$7,Ventas_Autos!$V$6:$V$205,12,Ventas_Autos!$Q$6:$Q$205,"Vendido") | N16: =SUM(B16:M16)
A17: Costo taller y repuestos | B17: =SUMIFS(Taller_Repuestos!$I$6:$I$205,Taller_Repuestos!$M$6:$M$205,Configuracion!$B$7,Taller_Repuestos!$N$6:$N$205,1) | C17: =SUMIFS(Taller_Repuestos!$I$6:$I$205,Taller_Repuestos!$M$6:$M$205,Configuracion!$B$7,Taller_Repuestos!$N$6:$N$205,2) | D17: =SUMIFS(Taller_Repuestos!$I$6:$I$205,Taller_Repuestos!$M$6:$M$205,Configuracion!$B$7,Taller_Repuestos!$N$6:$N$205,3) | E17: =SUMIFS(Taller_Repuestos!$I$6:$I$205,Taller_Repuestos!$M$6:$M$205,Configuracion!$B$7,Taller_Repuestos!$N$6:$N$205,4) | F17: =SUMIFS(Taller_Repuestos!$I$6:$I$205,Taller_Repuestos!$M$6:$M$205,Configuracion!$B$7,Taller_Repuestos!$N$6:$N$205,5) | G17: =SUMIFS(Taller_Repuestos!$I$6:$I$205,Taller_Repuestos!$M$6:$M$205,Configuracion!$B$7,Taller_Repuestos!$N$6:$N$205,6) | H17: =SUMIFS(Taller_Repuestos!$I$6:$I$205,Taller_Repuestos!$M$6:$M$205,Configuracion!$B$7,Taller_Repuestos!$N$6:$N$205,7) | I17: =SUMIFS(Taller_Repuestos!$I$6:$I$205,Taller_Repuestos!$M$6:$M$205,Configuracion!$B$7,Taller_Repuestos!$N$6:$N$205,8) | J17: =SUMIFS(Taller_Repuestos!$I$6:$I$205,Taller_Repuestos!$M$6:$M$205,Configuracion!$B$7,Taller_Repuestos!$N$6:$N$205,9) | K17: =SUMIFS(Taller_Repuestos!$I$6:$I$205,Taller_Repuestos!$M$6:$M$205,Configuracion!$B$7,Taller_Repuestos!$N$6:$N$205,10) | L17: =SUMIFS(Taller_Repuestos!$I$6:$I$205,Taller_Repuestos!$M$6:$M$205,Configuracion!$B$7,Taller_Repuestos!$N$6:$N$205,11) | M17: =SUMIFS(Taller_Repuestos!$I$6:$I$205,Taller_Repuestos!$M$6:$M$205,Configuracion!$B$7,Taller_Repuestos!$N$6:$N$205,12) | N17: =SUM(B17:M17)
A18: TOTAL COSTOS DIRECTOS | B18: =B16+B17 | C18: =C16+C17 | D18: =D16+D17 | E18: =E16+E17 | F18: =F16+F17 | G18: =G16+G17 | H18: =H16+H17 | I18: =I16+I17 | ... M18: =M16+M17 | N18: =SUM(B18:M18)
A19: MARGEN BRUTO | B19: =B13-B18 | C19: =C13-C18 | D19: =D13-D18 | E19: =E13-E18 | F19: =F13-F18 | G19: =G13-G18 | H19: =H13-H18 | I19: =I13-I18 | ... N19: =N13-N18
A20: Margen bruto % | B20: =IF(B13=0,"",B19/B13) | C20: =IF(C13=0,"",C19/C13) | D20: =IF(D13=0,"",D19/D13) | E20: =IF(E13=0,"",E19/E13) | F20: =IF(F13=0,"",F19/F13) | G20: =IF(G13=0,"",G19/G13) | H20: =IF(H13=0,"",H19/H13) | I20: =IF(I13=0,"",I19/I13) | ... N20: =IF(N13=0,"",N19/N13)
A22: GASTOS OPERACIONALES
A23: Gastos fijos | B23: =SUM(Gastos_Fijos!C6:C23) | C23: =SUM(Gastos_Fijos!D6:D23) | D23: =SUM(Gastos_Fijos!E6:E23) | E23: =SUM(Gastos_Fijos!F6:F23) | F23: =SUM(Gastos_Fijos!G6:G23) | G23: =SUM(Gastos_Fijos!H6:H23) | H23: =SUM(Gastos_Fijos!I6:I23) | I23: =SUM(Gastos_Fijos!J6:J23) | ... M23: =SUM(Gastos_Fijos!N6:N23) | N23: =SUM(B23:M23)
A24: Comisiones de vendedores | B24: =SUMIFS(Ventas_Autos!$P$6:$P$205,Ventas_Autos!$U$6:$U$205,Configuracion!$B$7,Ventas_Autos!$V$6:$V$205,1,Ventas_Autos!$Q$6:$Q$205,"Vendido") | C24: =SUMIFS(Ventas_Autos!$P$6:$P$205,Ventas_Autos!$U$6:$U$205,Configuracion!$B$7,Ventas_Autos!$V$6:$V$205,2,Ventas_Autos!$Q$6:$Q$205,"Vendido") | D24: =SUMIFS(Ventas_Autos!$P$6:$P$205,Ventas_Autos!$U$6:$U$205,Configuracion!$B$7,Ventas_Autos!$V$6:$V$205,3,Ventas_Autos!$Q$6:$Q$205,"Vendido") | E24: =SUMIFS(Ventas_Autos!$P$6:$P$205,Ventas_Autos!$U$6:$U$205,Configuracion!$B$7,Ventas_Autos!$V$6:$V$205,4,Ventas_Autos!$Q$6:$Q$205,"Vendido") | F24: =SUMIFS(Ventas_Autos!$P$6:$P$205,Ventas_Autos!$U$6:$U$205,Configuracion!$B$7,Ventas_Autos!$V$6:$V$205,5,Ventas_Autos!$Q$6:$Q$205,"Vendido") | G24: =SUMIFS(Ventas_Autos!$P$6:$P$205,Ventas_Autos!$U$6:$U$205,Configuracion!$B$7,Ventas_Autos!$V$6:$V$205,6,Ventas_Autos!$Q$6:$Q$205,"Vendido") | H24: =SUMIFS(Ventas_Autos!$P$6:$P$205,Ventas_Autos!$U$6:$U$205,Configuracion!$B$7,Ventas_Autos!$V$6:$V$205,7,Ventas_Autos!$Q$6:$Q$205,"Vendido") | I24: =SUMIFS(Ventas_Autos!$P$6:$P$205,Ventas_Autos!$U$6:$U$205,Configuracion!$B$7,Ventas_Autos!$V$6:$V$205,8,Ventas_Autos!$Q$6:$Q$205,"Vendido") | J24: =SUMIFS(Ventas_Autos!$P$6:$P$205,Ventas_Autos!$U$6:$U$205,Configuracion!$B$7,Ventas_Autos!$V$6:$V$205,9,Ventas_Autos!$Q$6:$Q$205,"Vendido") | K24: =SUMIFS(Ventas_Autos!$P$6:$P$205,Ventas_Autos!$U$6:$U$205,Configuracion!$B$7,Ventas_Autos!$V$6:$V$205,10,Ventas_Autos!$Q$6:$Q$205,"Vendido") | L24: =SUMIFS(Ventas_Autos!$P$6:$P$205,Ventas_Autos!$U$6:$U$205,Configuracion!$B$7,Ventas_Autos!$V$6:$V$205,11,Ventas_Autos!$Q$6:$Q$205,"Vendido") | M24: =SUMIFS(Ventas_Autos!$P$6:$P$205,Ventas_Autos!$U$6:$U$205,Configuracion!$B$7,Ventas_Autos!$V$6:$V$205,12,Ventas_Autos!$Q$6:$Q$205,"Vendido") | N24: =SUM(B24:M24)
A25: Gastos variables (sin comisiones) | B25: =SUM(Gastos_Variables!C6:C20) | C25: =SUM(Gastos_Variables!D6:D20) | D25: =SUM(Gastos_Variables!E6:E20) | E25: =SUM(Gastos_Variables!F6:F20) | F25: =SUM(Gastos_Variables!G6:G20) | G25: =SUM(Gastos_Variables!H6:H20) | H25: =SUM(Gastos_Variables!I6:I20) | I25: =SUM(Gastos_Variables!J6:J20) | ... M25: =SUM(Gastos_Variables!N6:N20) | N25: =SUM(B25:M25)
A26: TOTAL GASTOS OPERACIONALES | B26: =B23+B24+B25 | C26: =C23+C24+C25 | D26: =D23+D24+D25 | E26: =E23+E24+E25 | F26: =F23+F24+F25 | G26: =G23+G24+G25 | H26: =H23+H24+H25 | I26: =I23+I24+I25 | ... M26: =M23+M24+M25 | N26: =SUM(B26:M26)
A27: UTILIDAD OPERACIONAL | B27: =B19-B26 | C27: =C19-C26 | D27: =D19-D26 | E27: =E19-E26 | F27: =F19-F26 | G27: =G19-G26 | H27: =H19-H26 | I27: =I19-I26 | ... N27: =N19-N26
A28: Margen operacional % | B28: =IF(B13=0,"",B27/B13) | C28: =IF(C13=0,"",C27/C13) | D28: =IF(D13=0,"",D27/D13) | E28: =IF(E13=0,"",E27/E13) | F28: =IF(F13=0,"",F27/F13) | G28: =IF(G13=0,"",G27/G13) | H28: =IF(H13=0,"",H27/H13) | I28: =IF(I13=0,"",I27/I13) | ... N28: =IF(N13=0,"",N27/N13)
A30: IMPUESTO A LA RENTA ESTIMADO (no es el F29)
A31: Provisión 1ª categoría del mes | B31: =IF(B27>0,ROUND(B27*Configuracion!$B$13,0),0) | C31: =IF(C27>0,ROUND(C27*Configuracion!$B$13,0),0) | D31: =IF(D27>0,ROUND(D27*Configuracion!$B$13,0),0) | E31: =IF(E27>0,ROUND(E27*Configuracion!$B$13,0),0) | F31: =IF(F27>0,ROUND(F27*Configuracion!$B$13,0),0) | G31: =IF(G27>0,ROUND(G27*Configuracion!$B$13,0),0) | H31: =IF(H27>0,ROUND(H27*Configuracion!$B$13,0),0) | I31: =IF(I27>0,ROUND(I27*Configuracion!$B$13,0),0) | ... M31: =IF(M27>0,ROUND(M27*Configuracion!$B$13,0),0) | N31: =SUM(B31:M31)
A32: UTILIDAD NETA ESTIMADA | B32: =B27-B31 | C32: =C27-C31 | D32: =D27-D31 | E32: =E27-E31 | F32: =F27-F31 | G32: =G27-G31 | H32: =H27-H31 | I32: =I27-I31 | ... N32: =N27-N31

Sheet Ventas_Autos
A1: Ventas de autos — nuevos, usados y consignación
A2: Amarillo = datos. En consignación el ingreso es la comisión. En propios, el precio de venta. Estado Vendido entra al resultado; Stock no.
A3: IVA débito sale de la venta (o de la comisión). IVA crédito sale de la compra solo si Compra afecta IVA = Sí.
A5: N° | B5: Fecha compra | C5: Fecha venta | D5: Tipo | E5: Marca | F5: Modelo | G5: Año auto | H5: Patente | I5: Proveedor / consignante | J5: Compra afecta IVA | K5: Costo neto | L5: IVA compra | M5: Total compra | N5: Precio venta (c/IVA) | O5: Comisión consignación (c/IVA) | P5: Comisión vendedor (neto) | Q5: Estado | R5: Notas | S5: Año compra | T5: Mes compra | U5: Año venta | V5: Mes venta | W5: Ingreso neto automotora | X5: IVA débito | Y5: Costo en resultado | Z5: Margen de la unidad
A6: =IF(D6="","",ROW()-5) | B6: 46221 | C6: 46239 | D6: Usado | E6: Toyota | F6: Corolla | G6: 2019 | H6: RPKB12 | I6: Particular | J6: No | K6: 8500000 | L6: =IF(K6="","",IF(J6="Sí",ROUND(K6*Configuracion!$B$11,0),0)) | M6: =IF(K6="","",K6+L6) | N6: 11900000 | P6: 280000 | Q6: Vendido | R6: EJEMPLO — usado comprado a particular (sin crédito IVA) | S6: =IF(B6="","",YEAR(B6)) | T6: =IF(B6="","",MONTH(B6)) | U6: =IF(C6="","",YEAR(C6)) | V6: =IF(C6="","",MONTH(C6)) | W6: =IF(D6="","",IF(D6="Consignación",IF(O6="",0,ROUND(O6/(1+Configuracion!$B$11),0)),IF(N6="",0,ROUND(N6/(1+Configuracion!$B$11),0)))) | X6: =IF(W6="","",ROUND(W6*Configuracion!$B$11,0)) | Y6: =IF(OR(D6="",Q6<>"Vendido"),0,IF(D6="Consignación",0,IF(K6="",0,K6))) | Z6: =IF(Q6<>"Vendido","",W6-Y6-IF(P6="",0,P6))
A7: =IF(D7="","",ROW()-5) | B7: 46236 | C7: 46254 | D7: Nuevo | E7: Chevrolet | F7: Onix | G7: 2026 | H7: JKLP34 | I7: Importadora / marca | J7: Sí | K7: 10500000 | L7: =IF(K7="","",IF(J7="Sí",ROUND(K7*Configuracion!$B$11,0),0)) | M7: =IF(K7="","",K7+L7) | N7: 14900000 | P7: 350000 | Q7: Vendido | R7: EJEMPLO — nuevo con factura (sí hay crédito IVA) | S7: =IF(B7="","",YEAR(B7)) | T7: =IF(B7="","",MONTH(B7)) | U7: =IF(C7="","",YEAR(C7)) | V7: =IF(C7="","",MONTH(C7)) | W7: =IF(D7="","",IF(D7="Consignación",IF(O7="",0,ROUND(O7/(1+Configuracion!$B$11),0)),IF(N7="",0,ROUND(N7/(1+Configuracion!$B$11),0)))) | X7: =IF(W7="","",ROUND(W7*Configuracion!$B$11,0)) | Y7: =IF(OR(D7="",Q7<>"Vendido"),0,IF(D7="Consignación",0,IF(K7="",0,K7))) | Z7: =IF(Q7<>"Vendido","",W7-Y7-IF(P7="",0,P7))
A8: =IF(D8="","",ROW()-5) | B8: 46235 | C8: 46246 | D8: Consignación | E8: Hyundai | F8: Tucson | G8: 2021 | H8: LFTW90 | I8: Juan Pérez (consignante) | J8: No | K8: 0 | L8: =IF(K8="","",IF(J8="Sí",ROUND(K8*Configuracion!$B$11,0),0)) | M8: =IF(K8="","",K8+L8) | N8: 14500000 | O8: 950000 | P8: 120000 | Q8: Vendido | R8: EJEMPLO — ingreso = comisión, no el precio del auto | S8: =IF(B8="","",YEAR(B8)) | T8: =IF(B8="","",MONTH(B8)) | U8: =IF(C8="","",YEAR(C8)) | V8: =IF(C8="","",MONTH(C8)) | W8: =IF(D8="","",IF(D8="Consignación",IF(O8="",0,ROUND(O8/(1+Configuracion!$B$11),0)),IF(N8="",0,ROUND(N8/(1+Configuracion!$B$11),0)))) | X8: =IF(W8="","",ROUND(W8*Configuracion!$B$11,0)) | Y8: =IF(OR(D8="",Q8<>"Vendido"),0,IF(D8="Consignación",0,IF(K8="",0,K8))) | Z8: =IF(Q8<>"Vendido","",W8-Y8-IF(P8="",0,P8))
A9: =IF(D9="","",ROW()-5) | B9: 46256 | D9: Usado | E9: Mazda | F9: 3 | G9: 2018 | H9: PDKS21 | I9: Particular | J9: No | K9: 7200000 | L9: =IF(K9="","",IF(J9="Sí",ROUND(K9*Configuracion!$B$11,0),0)) | M9: =IF(K9="","",K9+L9) | Q9: Stock | R9: EJEMPLO — en patio, no entra al resultado hasta venderse | S9: =IF(B9="","",YEAR(B9)) | T9: =IF(B9="","",MONTH(B9)) | U9: =IF(C9="","",YEAR(C9)) | V9: =IF(C9="","",MONTH(C9)) | W9: =IF(D9="","",IF(D9="Consignación",IF(O9="",0,ROUND(O9/(1+Configuracion!$B$11),0)),IF(N9="",0,ROUND(N9/(1+Configuracion!$B$11),0)))) | X9: =IF(W9="","",ROUND(W9*Configuracion!$B$11,0)) | Y9: =IF(OR(D9="",Q9<>"Vendido"),0,IF(D9="Consignación",0,IF(K9="",0,K9))) | Z9: =IF(Q9<>"Vendido","",W9-Y9-IF(P9="",0,P9))
A10: =IF(D10="","",ROW()-5) | L10: =IF(K10="","",IF(J10="Sí",ROUND(K10*Configuracion!$B$11,0),0)) | M10: =IF(K10="","",K10+L10) | S10: =IF(B10="","",YEAR(B10)) | T10: =IF(B10="","",MONTH(B10)) | U10: =IF(C10="","",YEAR(C10)) | V10: =IF(C10="","",MONTH(C10)) | W10: =IF(D10="","",IF(D10="Consignación",IF(O10="",0,ROUND(O10/(1+Configuracion!$B$11),0)),IF(N10="",0,ROUND(N10/(1+Configuracion!$B$11),0)))) | X10: =IF(W10="","",ROUND(W10*Configuracion!$B$11,0)) | Y10: =IF(OR(D10="",Q10<>"Vendido"),0,IF(D10="Consignación",0,IF(K10="",0,K10))) | Z10: =IF(Q10<>"Vendido","",W10-Y10-IF(P10="",0,P10))
A11: =IF(D11="","",ROW()-5) | L11: =IF(K11="","",IF(J11="Sí",ROUND(K11*Configuracion!$B$11,0),0)) | M11: =IF(K11="","",K11+L11) | S11: =IF(B11="","",YEAR(B11)) | T11: =IF(B11="","",MONTH(B11)) | U11: =IF(C11="","",YEAR(C11)) | V11: =IF(C11="","",MONTH(C11)) | W11: =IF(D11="","",IF(D11="Consignación",IF(O11="",0,ROUND(O11/(1+Configuracion!$B$11),0)),IF(N11="",0,ROUND(N11/(1+Configuracion!$B$11),0)))) | X11: =IF(W11="","",ROUND(W11*Configuracion!$B$11,0)) | Y11: =IF(OR(D11="",Q11<>"Vendido"),0,IF(D11="Consignación",0,IF(K11="",0,K11))) | Z11: =IF(Q11<>"Vendido","",W11-Y11-IF(P11="",0,P11))
A12: =IF(D12="","",ROW()-5) | L12: =IF(K12="","",IF(J12="Sí",ROUND(K12*Configuracion!$B$11,0),0)) | M12: =IF(K12="","",K12+L12) | S12: =IF(B12="","",YEAR(B12)) | T12: =IF(B12="","",MONTH(B12)) | U12: =IF(C12="","",YEAR(C12)) | V12: =IF(C12="","",MONTH(C12)) | W12: =IF(D12="","",IF(D12="Consignación",IF(O12="",0,ROUND(O12/(1+Configuracion!$B$11),0)),IF(N12="",0,ROUND(N12/(1+Configuracion!$B$11),0)))) | X12: =IF(W12="","",ROUND(W12*Configuracion!$B$11,0)) | Y12: =IF(OR(D12="",Q12<>"Vendido"),0,IF(D12="Consignación",0,IF(K12="",0,K12))) | Z12: =IF(Q12<>"Vendido","",W12-Y12-IF(P12="",0,P12))
A13: =IF(D13="","",ROW()-5) | L13: =IF(K13="","",IF(J13="Sí",ROUND(K13*Configuracion!$B$11,0),0)) | M13: =IF(K13="","",K13+L13) | S13: =IF(B13="","",YEAR(B13)) | T13: =IF(B13="","",MONTH(B13)) | U13: =IF(C13="","",YEAR(C13)) | V13: =IF(C13="","",MONTH(C13)) | W13: =IF(D13="","",IF(D13="Consignación",IF(O13="",0,ROUND(O13/(1+Configuracion!$B$11),0)),IF(N13="",0,ROUND(N13/(1+Configuracion!$B$11),0)))) | X13: =IF(W13="","",ROUND(W13*Configuracion!$B$11,0)) | Y13: =IF(OR(D13="",Q13<>"Vendido"),0,IF(D13="Consignación",0,IF(K13="",0,K13))) | Z13: =IF(Q13<>"Vendido","",W13-Y13-IF(P13="",0,P13))
A14: =IF(D14="","",ROW()-5) | L14: =IF(K14="","",IF(J14="Sí",ROUND(K14*Configuracion!$B$11,0),0)) | M14: =IF(K14="","",K14+L14) | S14: =IF(B14="","",YEAR(B14)) | T14: =IF(B14="","",MONTH(B14)) | U14: =IF(C14="","",YEAR(C14)) | V14: =IF(C14="","",MONTH(C14)) | W14: =IF(D14="","",IF(D14="Consignación",IF(O14="",0,ROUND(O14/(1+Configuracion!$B$11),0)),IF(N14="",0,ROUND(N14/(1+Configuracion!$B$11),0)))) | X14: =IF(W14="","",ROUND(W14*Configuracion!$B$11,0)) | Y14: =IF(OR(D14="",Q14<>"Vendido"),0,IF(D14="Consignación",0,IF(K14="",0,K14))) | Z14: =IF(Q14<>"Vendido","",W14-Y14-IF(P14="",0,P14))
A15: =IF(D15="","",ROW()-5) | L15: =IF(K15="","",IF(J15="Sí",ROUND(K15*Configuracion!$B$11,0),0)) | M15: =IF(K15="","",K15+L15) | S15: =IF(B15="","",YEAR(B15)) | T15: =IF(B15="","",MONTH(B15)) | U15: =IF(C15="","",YEAR(C15)) | V15: =IF(C15="","",MONTH(C15)) | W15: =IF(D15="","",IF(D15="Consignación",IF(O15="",0,ROUND(O15/(1+Configuracion!$B$11),0)),IF(N15="",0,ROUND(N15/(1+Configuracion!$B$11),0)))) | X15: =IF(W15="","",ROUND(W15*Configuracion!$B$11,0)) | Y15: =IF(OR(D15="",Q15<>"Vendido"),0,IF(D15="Consignación",0,IF(K15="",0,K15))) | Z15: =IF(Q15<>"Vendido","",W15-Y15-IF(P15="",0,P15))
A16: =IF(D16="","",ROW()-5) | L16: =IF(K16="","",IF(J16="Sí",ROUND(K16*Configuracion!$B$11,0),0)) | M16: =IF(K16="","",K16+L16) | S16: =IF(B16="","",YEAR(B16)) | T16: =IF(B16="","",MONTH(B16)) | U16: =IF(C16="","",YEAR(C16)) | V16: =IF(C16="","",MONTH(C16)) | W16: =IF(D16="","",IF(D16="Consignación",IF(O16="",0,ROUND(O16/(1+Configuracion!$B$11),0)),IF(N16="",0,ROUND(N16/(1+Configuracion!$B$11),0)))) | X16: =IF(W16="","",ROUND(W16*Configuracion!$B$11,0)) | Y16: =IF(OR(D16="",Q16<>"Vendido"),0,IF(D16="Consignación",0,IF(K16="",0,K16))) | Z16: =IF(Q16<>"Vendido","",W16-Y16-IF(P16="",0,P16))
A17: =IF(D17="","",ROW()-5) | L17: =IF(K17="","",IF(J17="Sí",ROUND(K17*Configuracion!$B$11,0),0)) | M17: =IF(K17="","",K17+L17) | S17: =IF(B17="","",YEAR(B17)) | T17: =IF(B17="","",MONTH(B17)) | U17: =IF(C17="","",YEAR(C17)) | V17: =IF(C17="","",MONTH(C17)) | W17: =IF(D17="","",IF(D17="Consignación",IF(O17="",0,ROUND(O17/(1+Configuracion!$B$11),0)),IF(N17="",0,ROUND(N17/(1+Configuracion!$B$11),0)))) | X17: =IF(W17="","",ROUND(W17*Configuracion!$B$11,0)) | Y17: =IF(OR(D17="",Q17<>"Vendido"),0,IF(D17="Consignación",0,IF(K17="",0,K17))) | Z17: =IF(Q17<>"Vendido","",W17-Y17-IF(P17="",0,P17))
A18: =IF(D18="","",ROW()-5) | L18: =IF(K18="","",IF(J18="Sí",ROUND(K18*Configuracion!$B$11,0),0)) | M18: =IF(K18="","",K18+L18) | S18: =IF(B18="","",YEAR(B18)) | T18: =IF(B18="","",MONTH(B18)) | U18: =IF(C18="","",YEAR(C18)) | V18: =IF(C18="","",MONTH(C18)) | W18: =IF(D18="","",IF(D18="Consignación",IF(O18="",0,ROUND(O18/(1+Configuracion!$B$11),0)),IF(N18="",0,ROUND(N18/(1+Configuracion!$B$11),0)))) | X18: =IF(W18="","",ROUND(W18*Configuracion!$B$11,0)) | Y18: =IF(OR(D18="",Q18<>"Vendido"),0,IF(D18="Consignación",0,IF(K18="",0,K18))) | Z18: =IF(Q18<>"Vendido","",W18-Y18-IF(P18="",0,P18))
A19: =IF(D19="","",ROW()-5) | L19: =IF(K19="","",IF(J19="Sí",ROUND(K19*Configuracion!$B$11,0),0)) | M19: =IF(K19="","",K19+L19) | S19: =IF(B19="","",YEAR(B19)) | T19: =IF(B19="","",MONTH(B19)) | U19: =IF(C19="","",YEAR(C19)) | V19: =IF(C19="","",MONTH(C19)) | W19: =IF(D19="","",IF(D19="Consignación",IF(O19="",0,ROUND(O19/(1+Configuracion!$B$11),0)),IF(N19="",0,ROUND(N19/(1+Configuracion!$B$11),0)))) | X19: =IF(W19="","",ROUND(W19*Configuracion!$B$11,0)) | Y19: =IF(OR(D19="",Q19<>"Vendido"),0,IF(D19="Consignación",0,IF(K19="",0,K19))) | Z19: =IF(Q19<>"Vendido","",W19-Y19-IF(P19="",0,P19))
A20: =IF(D20="","",ROW()-5) | L20: =IF(K20="","",IF(J20="Sí",ROUND(K20*Configuracion!$B$11,0),0)) | M20: =IF(K20="","",K20+L20) | S20: =IF(B20="","",YEAR(B20)) | T20: =IF(B20="","",MONTH(B20)) | U20: =IF(C20="","",YEAR(C20)) | V20: =IF(C20="","",MONTH(C20)) | W20: =IF(D20="","",IF(D20="Consignación",IF(O20="",0,ROUND(O20/(1+Configuracion!$B$11),0)),IF(N20="",0,ROUND(N20/(1+Configuracion!$B$11),0)))) | X20: =IF(W20="","",ROUND(W20*Configuracion!$B$11,0)) | Y20: =IF(OR(D20="",Q20<>"Vendido"),0,IF(D20="Consignación",0,IF(K20="",0,K20))) | Z20: =IF(Q20<>"Vendido","",W20-Y20-IF(P20="",0,P20))
A21: =IF(D21="","",ROW()-5) | L21: =IF(K21="","",IF(J21="Sí",ROUND(K21*Configuracion!$B$11,0),0)) | M21: =IF(K21="","",K21+L21) | S21: =IF(B21="","",YEAR(B21)) | T21: =IF(B21="","",MONTH(B21)) | U21: =IF(C21="","",YEAR(C21)) | V21: =IF(C21="","",MONTH(C21)) | W21: =IF(D21="","",IF(D21="Consignación",IF(O21="",0,ROUND(O21/(1+Configuracion!$B$11),0)),IF(N21="",0,ROUND(N21/(1+Configuracion!$B$11),0)))) | X21: =IF(W21="","",ROUND(W21*Configuracion!$B$11,0)) | Y21: =IF(OR(D21="",Q21<>"Vendido"),0,IF(D21="Consignación",0,IF(K21="",0,K21))) | Z21: =IF(Q21<>"Vendido","",W21-Y21-IF(P21="",0,P21))
... A205: =IF(D205="","",ROW()-5) | L205: =IF(K205="","",IF(J205="Sí",ROUND(K205*Configuracion!$B$11,0),0)) | M205: =IF(K205="","",K205+L205) | S205: =IF(B205="","",YEAR(B205)) | T205: =IF(B205="","",MONTH(B205)) | U205: =IF(C205="","",YEAR(C205)) | V205: =IF(C205="","",MONTH(C205)) | W205: =IF(D205="","",IF(D205="Consignación",IF(O205="",0,ROUND(O205/(1+Configuracion!$B$11),0)),IF(N205="",0,ROUND(N205/(1+Configuracion!$B$11),0)))) | X205: =IF(W205="","",ROUND(W205*Configuracion!$B$11,0)) | Y205: =IF(OR(D205="",Q205<>"Vendido"),0,IF(D205="Consignación",0,IF(K205="",0,K205))) | Z205: =IF(Q205<>"Vendido","",W205-Y205-IF(P205="",0,P205))

Sheet Taller_Repuestos
A1: Taller y repuestos
A2: Mano de obra, OT y mostrador. Neto = sin IVA. El margen es venta neta − costo neto.
A3: Si el costo viene con factura, marca Costo afecto IVA = Sí para que sume al crédito fiscal.
A5: Fecha | B5: Tipo | C5: Documento / OT | D5: Cliente | E5: Descripción | F5: Venta neta | G5: IVA venta | H5: Total venta | I5: Costo neto | J5: Costo afecto IVA | K5: IVA crédito | L5: Margen | M5: Año | N5: Mes
A6: 46242 | B6: Taller | C6: OT-0145 | D6: Cliente taller | E6: Service 10.000 km | F6: 350000 | G6: =IF(F6="","",ROUND(F6*Configuracion!$B$11,0)) | H6: =IF(F6="","",F6+G6) | I6: 80000 | J6: Sí | K6: =IF(I6="","",IF(J6="Sí",ROUND(I6*Configuracion!$B$11,0),0)) | L6: =IF(F6="","",F6-IF(I6="",0,I6)) | M6: =IF(A6="","",YEAR(A6)) | N6: =IF(A6="","",MONTH(A6))
A7: 46249 | B7: Repuestos | C7: FAC-889 | D7: Mostrador | E7: Filtro + pastillas | F7: 180000 | G7: =IF(F7="","",ROUND(F7*Configuracion!$B$11,0)) | H7: =IF(F7="","",F7+G7) | I7: 95000 | J7: Sí | K7: =IF(I7="","",IF(J7="Sí",ROUND(I7*Configuracion!$B$11,0),0)) | L7: =IF(F7="","",F7-IF(I7="",0,I7)) | M7: =IF(A7="","",YEAR(A7)) | N7: =IF(A7="","",MONTH(A7))
A8: 46255 | B8: Taller | C8: OT-0152 | D8: Preparación unidad | E8: Pintura paragolpes | F8: 220000 | G8: =IF(F8="","",ROUND(F8*Configuracion!$B$11,0)) | H8: =IF(F8="","",F8+G8) | I8: 110000 | J8: Sí | K8: =IF(I8="","",IF(J8="Sí",ROUND(I8*Configuracion!$B$11,0),0)) | L8: =IF(F8="","",F8-IF(I8="",0,I8)) | M8: =IF(A8="","",YEAR(A8)) | N8: =IF(A8="","",MONTH(A8))
G9: =IF(F9="","",ROUND(F9*Configuracion!$B$11,0)) | H9: =IF(F9="","",F9+G9) | K9: =IF(I9="","",IF(J9="Sí",ROUND(I9*Configuracion!$B$11,0),0)) | L9: =IF(F9="","",F9-IF(I9="",0,I9)) | M9: =IF(A9="","",YEAR(A9)) | N9: =IF(A9="","",MONTH(A9))
G10: =IF(F10="","",ROUND(F10*Configuracion!$B$11,0)) | H10: =IF(F10="","",F10+G10) | K10: =IF(I10="","",IF(J10="Sí",ROUND(I10*Configuracion!$B$11,0),0)) | L10: =IF(F10="","",F10-IF(I10="",0,I10)) | M10: =IF(A10="","",YEAR(A10)) | N10: =IF(A10="","",MONTH(A10))
G11: =IF(F11="","",ROUND(F11*Configuracion!$B$11,0)) | H11: =IF(F11="","",F11+G11) | K11: =IF(I11="","",IF(J11="Sí",ROUND(I11*Configuracion!$B$11,0),0)) | L11: =IF(F11="","",F11-IF(I11="",0,I11)) | M11: =IF(A11="","",YEAR(A11)) | N11: =IF(A11="","",MONTH(A11))
G12: =IF(F12="","",ROUND(F12*Configuracion!$B$11,0)) | H12: =IF(F12="","",F12+G12) | K12: =IF(I12="","",IF(J12="Sí",ROUND(I12*Configuracion!$B$11,0),0)) | L12: =IF(F12="","",F12-IF(I12="",0,I12)) | M12: =IF(A12="","",YEAR(A12)) | N12: =IF(A12="","",MONTH(A12))
G13: =IF(F13="","",ROUND(F13*Configuracion!$B$11,0)) | H13: =IF(F13="","",F13+G13) | K13: =IF(I13="","",IF(J13="Sí",ROUND(I13*Configuracion!$B$11,0),0)) | L13: =IF(F13="","",F13-IF(I13="",0,I13)) | M13: =IF(A13="","",YEAR(A13)) | N13: =IF(A13="","",MONTH(A13))
G14: =IF(F14="","",ROUND(F14*Configuracion!$B$11,0)) | H14: =IF(F14="","",F14+G14) | K14: =IF(I14="","",IF(J14="Sí",ROUND(I14*Configuracion!$B$11,0),0)) | L14: =IF(F14="","",F14-IF(I14="",0,I14)) | M14: =IF(A14="","",YEAR(A14)) | N14: =IF(A14="","",MONTH(A14))
G15: =IF(F15="","",ROUND(F15*Configuracion!$B$11,0)) | H15: =IF(F15="","",F15+G15) | K15: =IF(I15="","",IF(J15="Sí",ROUND(I15*Configuracion!$B$11,0),0)) | L15: =IF(F15="","",F15-IF(I15="",0,I15)) | M15: =IF(A15="","",YEAR(A15)) | N15: =IF(A15="","",MONTH(A15))
G16: =IF(F16="","",ROUND(F16*Configuracion!$B$11,0)) | H16: =IF(F16="","",F16+G16) | K16: =IF(I16="","",IF(J16="Sí",ROUND(I16*Configuracion!$B$11,0),0)) | L16: =IF(F16="","",F16-IF(I16="",0,I16)) | M16: =IF(A16="","",YEAR(A16)) | N16: =IF(A16="","",MONTH(A16))
G17: =IF(F17="","",ROUND(F17*Configuracion!$B$11,0)) | H17: =IF(F17="","",F17+G17) | K17: =IF(I17="","",IF(J17="Sí",ROUND(I17*Configuracion!$B$11,0),0)) | L17: =IF(F17="","",F17-IF(I17="",0,I17)) | M17: =IF(A17="","",YEAR(A17)) | N17: =IF(A17="","",MONTH(A17))
G18: =IF(F18="","",ROUND(F18*Configuracion!$B$11,0)) | H18: =IF(F18="","",F18+G18) | K18: =IF(I18="","",IF(J18="Sí",ROUND(I18*Configuracion!$B$11,0),0)) | L18: =IF(F18="","",F18-IF(I18="",0,I18)) | M18: =IF(A18="","",YEAR(A18)) | N18: =IF(A18="","",MONTH(A18))
G19: =IF(F19="","",ROUND(F19*Configuracion!$B$11,0)) | H19: =IF(F19="","",F19+G19) | K19: =IF(I19="","",IF(J19="Sí",ROUND(I19*Configuracion!$B$11,0),0)) | L19: =IF(F19="","",F19-IF(I19="",0,I19)) | M19: =IF(A19="","",YEAR(A19)) | N19: =IF(A19="","",MONTH(A19))
G20: =IF(F20="","",ROUND(F20*Configuracion!$B$11,0)) | H20: =IF(F20="","",F20+G20) | K20: =IF(I20="","",IF(J20="Sí",ROUND(I20*Configuracion!$B$11,0),0)) | L20: =IF(F20="","",F20-IF(I20="",0,I20)) | M20: =IF(A20="","",YEAR(A20)) | N20: =IF(A20="","",MONTH(A20))
... G205: =IF(F205="","",ROUND(F205*Configuracion!$B$11,0)) | H205: =IF(F205="","",F205+G205) | K205: =IF(I205="","",IF(J205="Sí",ROUND(I205*Configuracion!$B$11,0),0)) | L205: =IF(F205="","",F205-IF(I205="",0,I205)) | M205: =IF(A205="","",YEAR(A205)) | N205: =IF(A205="","",MONTH(A205))

Sheet Otros_Ingresos
A1: Otros ingresos
A2: Financiamiento, transferencias cobradas al cliente, arriendo de patio, etc.
A5: Fecha | B5: Categoría | C5: Descripción | D5: Neto | E5: Afecto IVA | F5: IVA | G5: Total | H5: Año | I5: Mes
A6: 46252 | B6: Gestión de financiamiento | C6: EJEMPLO — comisión financiera | D6: 120000 | E6: Sí | F6: =IF(D6="","",IF(E6="Sí",ROUND(D6*Configuracion!$B$11,0),0)) | G6: =IF(D6="","",D6+F6) | H6: =IF(A6="","",YEAR(A6)) | I6: =IF(A6="","",MONTH(A6))
F7: =IF(D7="","",IF(E7="Sí",ROUND(D7*Configuracion!$B$11,0),0)) | G7: =IF(D7="","",D7+F7) | H7: =IF(A7="","",YEAR(A7)) | I7: =IF(A7="","",MONTH(A7))
F8: =IF(D8="","",IF(E8="Sí",ROUND(D8*Configuracion!$B$11,0),0)) | G8: =IF(D8="","",D8+F8) | H8: =IF(A8="","",YEAR(A8)) | I8: =IF(A8="","",MONTH(A8))
F9: =IF(D9="","",IF(E9="Sí",ROUND(D9*Configuracion!$B$11,0),0)) | G9: =IF(D9="","",D9+F9) | H9: =IF(A9="","",YEAR(A9)) | I9: =IF(A9="","",MONTH(A9))
F10: =IF(D10="","",IF(E10="Sí",ROUND(D10*Configuracion!$B$11,0),0)) | G10: =IF(D10="","",D10+F10) | H10: =IF(A10="","",YEAR(A10)) | I10: =IF(A10="","",MONTH(A10))
F11: =IF(D11="","",IF(E11="Sí",ROUND(D11*Configuracion!$B$11,0),0)) | G11: =IF(D11="","",D11+F11) | H11: =IF(A11="","",YEAR(A11)) | I11: =IF(A11="","",MONTH(A11))
F12: =IF(D12="","",IF(E12="Sí",ROUND(D12*Configuracion!$B$11,0),0)) | G12: =IF(D12="","",D12+F12) | H12: =IF(A12="","",YEAR(A12)) | I12: =IF(A12="","",MONTH(A12))
F13: =IF(D13="","",IF(E13="Sí",ROUND(D13*Configuracion!$B$11,0),0)) | G13: =IF(D13="","",D13+F13) | H13: =IF(A13="","",YEAR(A13)) | I13: =IF(A13="","",MONTH(A13))
F14: =IF(D14="","",IF(E14="Sí",ROUND(D14*Configuracion!$B$11,0),0)) | G14: =IF(D14="","",D14+F14) | H14: =IF(A14="","",YEAR(A14)) | I14: =IF(A14="","",MONTH(A14))
F15: =IF(D15="","",IF(E15="Sí",ROUND(D15*Configuracion!$B$11,0),0)) | G15: =IF(D15="","",D15+F15) | H15: =IF(A15="","",YEAR(A15)) | I15: =IF(A15="","",MONTH(A15))
F16: =IF(D16="","",IF(E16="Sí",ROUND(D16*Configuracion!$B$11,0),0)) | G16: =IF(D16="","",D16+F16) | H16: =IF(A16="","",YEAR(A16)) | I16: =IF(A16="","",MONTH(A16))
F17: =IF(D17="","",IF(E17="Sí",ROUND(D17*Configuracion!$B$11,0),0)) | G17: =IF(D17="","",D17+F17) | H17: =IF(A17="","",YEAR(A17)) | I17: =IF(A17="","",MONTH(A17))
F18: =IF(D18="","",IF(E18="Sí",ROUND(D18*Configuracion!$B$11,0),0)) | G18: =IF(D18="","",D18+F18) | H18: =IF(A18="","",YEAR(A18)) | I18: =IF(A18="","",MONTH(A18))
... F105: =IF(D105="","",IF(E105="Sí",ROUND(D105*Configuracion!$B$11,0),0)) | G105: =IF(D105="","",D105+F105) | H105: =IF(A105="","",YEAR(A105)) | I105: =IF(A105="","",MONTH(A105))

Sheet Gastos_Fijos
A1: Gastos fijos
A2: Costos que se pagan aunque no vendas. Completa la columna de cada mes en neto.
A3: Los montos de cada mes salen de la hoja Comprobantes (Telegram). Afecto IVA de esta columna es la referencia del concepto.
A5: Concepto | B5: Afecto IVA | C5: Enero | D5: Febrero | E5: Marzo | F5: Abril | G5: Mayo | H5: Junio | I5: Julio | J5: Agosto | K5: Septiembre | L5: Octubre | M5: Noviembre | N5: Diciembre | O5: Total año | P5: IVA del año | Q5: Este mes | R5: IVA este mes
